ERROR Thu, 28 Jul 2011 09:08:43 +0200 views 37908 140735191181664 lala
ERROR Thu, 28 Jul 2011 09:08:43 +0200 views 37908 140735191181664 Exception in ProductPictureUploadView: 
ERROR Thu, 28 Jul 2011 09:10:05 +0200 views 37953 140735191181664 lala
ERROR Thu, 28 Jul 2011 09:10:15 +0200 views 37953 140735191181664 lala
ERROR Thu, 28 Jul 2011 09:10:15 +0200 views 37953 140735191181664 Exception in ProductPictureUploadview
Traceback (most recent call last):
  File "backend/views.py", line 125, in _save_upload
    f = FileIO(os.path.join(path, filename), "r+b")
IOError: [Errno 2] No such file or directory: '/Users/guillaume/Projects/BTS/backtoshops/media/product_pictures/moi_twitter.png'
ERROR Thu, 28 Jul 2011 09:12:42 +0200 views 37953 140735191181664 lala
ERROR Thu, 28 Jul 2011 09:12:42 +0200 views 37953 140735191181664 Exception in ProductPictureUploadview
Traceback (most recent call last):
  File "backend/views.py", line 125, in _save_upload
    f = FileIO(os.path.join(path, filename), "r+b")
IOError: [Errno 2] No such file or directory: '/Users/guillaume/Projects/BTS/backtoshops/media/product_pictures/statsMap.png'
ERROR Thu, 28 Jul 2011 09:20:11 +0200 views 41882 140735191181664 lala
ERROR Thu, 28 Jul 2011 09:20:11 +0200 views 41882 140735191181664 Exception in ProductPictureUploadview
Traceback (most recent call last):
  File "backend/views.py", line 125, in _save_upload
    f = FileIO(os.path.join(path, filename), "r+b")
IOError: [Errno 2] No such file or directory: '/Users/guillaume/Projects/BTS/backtoshops/media/product_pictures/china.jpg'
ERROR Thu, 28 Jul 2011 09:22:42 +0200 views 41936 140735191181664 lala
ERROR Thu, 28 Jul 2011 09:22:50 +0200 views 41936 140735191181664 lala
ERROR Thu, 28 Jul 2011 10:12:54 +0200 views 41936 140735191181664 lala
ERROR Thu, 08 May 2014 08:47:40 +0000 base 1545 140348547102464 Internal Server Error: /webservice/1.0/private/payment/init
Traceback (most recent call last):
  File "/home/ada/backtoshops-env/local/lib/python2.7/site-packages/django/core/handlers/base.py", line 115, in get_response
    response = callback(request, *callback_args, **callback_kwargs)
  File "/home/ada/backtoshops-env/local/lib/python2.7/site-packages/django/views/decorators/csrf.py", line 77, in wrapped_view
    return view_func(*args, **kwargs)
  File "/home/ada/svn/backtoshops/backtoshops/webservice/views.py", line 1067, in payment_init
    resp = remote_payment_init(data)
  File "/home/ada/svn/backtoshops/backtoshops/common/transaction.py", line 16, in remote_payment_init
    settings.PRIVATE_KEY_PATH)
  File "/home/ada/backtoshops-env/local/lib/python2.7/site-packages/B2SCrypto-0.0.2-py2.7.egg/B2SCrypto/utils.py", line 161, in gen_encrypt_json_context
    pub_key = get_key_from_remote(api_key_uri)
  File "/home/ada/backtoshops-env/local/lib/python2.7/site-packages/B2SCrypto-0.0.2-py2.7.egg/B2SCrypto/utils.py", line 190, in get_key_from_remote
    resp = urllib2.urlopen(uri)
  File "/usr/lib/python2.7/urllib2.py", line 126, in urlopen
    return _opener.open(url, data, timeout)
  File "/usr/lib/python2.7/urllib2.py", line 400, in open
    response = self._open(req, data)
  File "/usr/lib/python2.7/urllib2.py", line 418, in _open
    '_open', req)
  File "/usr/lib/python2.7/urllib2.py", line 378, in _call_chain
    result = func(*args)
  File "/usr/lib/python2.7/urllib2.py", line 1207, in http_open
    return self.do_open(httplib.HTTPConnection, req)
  File "/usr/lib/python2.7/urllib2.py", line 1177, in do_open
    raise URLError(err)
URLError: <urlopen error [Errno 111] Connection refused>
ERROR Thu, 08 May 2014 08:48:13 +0000 base 1545 140348547102464 Internal Server Error: /webservice/1.0/private/payment/init
Traceback (most recent call last):
  File "/home/ada/backtoshops-env/local/lib/python2.7/site-packages/django/core/handlers/base.py", line 115, in get_response
    response = callback(request, *callback_args, **callback_kwargs)
  File "/home/ada/backtoshops-env/local/lib/python2.7/site-packages/django/views/decorators/csrf.py", line 77, in wrapped_view
    return view_func(*args, **kwargs)
  File "/home/ada/svn/backtoshops/backtoshops/webservice/views.py", line 1070, in payment_init
    content = {'pm_init': resp['pm_init'],
KeyError: 'pm_init'
ERROR Thu, 08 May 2014 08:52:02 +0000 base 2953 140361654761216 Internal Server Error: /webservice/1.0/private/payment/init
Traceback (most recent call last):
  File "/home/ada/backtoshops-env/local/lib/python2.7/site-packages/django/core/handlers/base.py", line 115, in get_response
    response = callback(request, *callback_args, **callback_kwargs)
  File "/home/ada/backtoshops-env/local/lib/python2.7/site-packages/django/views/decorators/csrf.py", line 77, in wrapped_view
    return view_func(*args, **kwargs)
  File "/home/ada/svn/backtoshops/backtoshops/webservice/views.py", line 1067, in payment_init
    resp = remote_payment_init(data)
  File "/home/ada/svn/backtoshops/backtoshops/common/transaction.py", line 16, in remote_payment_init
    settings.PRIVATE_KEY_PATH)
  File "/home/ada/backtoshops-env/local/lib/python2.7/site-packages/B2SCrypto-0.0.2-py2.7.egg/B2SCrypto/utils.py", line 161, in gen_encrypt_json_context
    pub_key = get_key_from_remote(api_key_uri)
  File "/home/ada/backtoshops-env/local/lib/python2.7/site-packages/B2SCrypto-0.0.2-py2.7.egg/B2SCrypto/utils.py", line 190, in get_key_from_remote
    resp = urllib2.urlopen(uri)
  File "/usr/lib/python2.7/urllib2.py", line 126, in urlopen
    return _opener.open(url, data, timeout)
  File "/usr/lib/python2.7/urllib2.py", line 400, in open
    response = self._open(req, data)
  File "/usr/lib/python2.7/urllib2.py", line 418, in _open
    '_open', req)
  File "/usr/lib/python2.7/urllib2.py", line 378, in _call_chain
    result = func(*args)
  File "/usr/lib/python2.7/urllib2.py", line 1207, in http_open
    return self.do_open(httplib.HTTPConnection, req)
  File "/usr/lib/python2.7/urllib2.py", line 1177, in do_open
    raise URLError(err)
URLError: <urlopen error [Errno 111] Connection refused>
ERROR Thu, 08 May 2014 08:52:38 +0000 base 3705 140308054341376 Internal Server Error: /sales/list/current/
Traceback (most recent call last):
  File "/home/ada/backtoshops-env/local/lib/python2.7/site-packages/django/core/handlers/base.py", line 140, in get_response
    response = response.render()
  File "/home/ada/backtoshops-env/local/lib/python2.7/site-packages/django/template/response.py", line 105, in render
    self.content = self.rendered_content
  File "/home/ada/backtoshops-env/local/lib/python2.7/site-packages/django/template/response.py", line 82, in rendered_content
    content = template.render(context)
  File "/home/ada/backtoshops-env/local/lib/python2.7/site-packages/django/template/base.py", line 140, in render
    return self._render(context)
  File "/home/ada/backtoshops-env/local/lib/python2.7/site-packages/django/template/base.py", line 134, in _render
    return self.nodelist.render(context)
  File "/home/ada/backtoshops-env/local/lib/python2.7/site-packages/django/template/base.py", line 830, in render
    bit = self.render_node(node, context)
  File "/home/ada/backtoshops-env/local/lib/python2.7/site-packages/django/template/debug.py", line 74, in render_node
    return node.render(context)
  File "/home/ada/backtoshops-env/local/lib/python2.7/site-packages/django/template/loader_tags.py", line 124, in render
    return compiled_parent._render(context)
  File "/home/ada/backtoshops-env/local/lib/python2.7/site-packages/django/template/base.py", line 134, in _render
    return self.nodelist.render(context)
  File "/home/ada/backtoshops-env/local/lib/python2.7/site-packages/django/template/base.py", line 830, in render
    bit = self.render_node(node, context)
  File "/home/ada/backtoshops-env/local/lib/python2.7/site-packages/django/template/debug.py", line 74, in render_node
    return node.render(context)
  File "/home/ada/backtoshops-env/local/lib/python2.7/site-packages/django/template/loader_tags.py", line 63, in render
    result = block.nodelist.render(context)
  File "/home/ada/backtoshops-env/local/lib/python2.7/site-packages/django/template/base.py", line 830, in render
    bit = self.render_node(node, context)
  File "/home/ada/backtoshops-env/local/lib/python2.7/site-packages/django/template/debug.py", line 74, in render_node
    return node.render(context)
  File "/home/ada/backtoshops-env/local/lib/python2.7/site-packages/django/template/defaulttags.py", line 188, in render
    nodelist.append(node.render(context))
  File "/home/ada/backtoshops-env/local/lib/python2.7/site-packages/sorl/thumbnail/templatetags/thumbnail.py", line 45, in render
    return self._render(context)
  File "/home/ada/backtoshops-env/local/lib/python2.7/site-packages/sorl/thumbnail/templatetags/thumbnail.py", line 97, in _render
    file_, geometry, **options
  File "/home/ada/svn/backtoshops/backtoshops/../backtoshops/init.py", line 8, in get_thumbnail
    thumbnail = super(CustomThumbnailBackend, self).get_thumbnail(file, geometry_string, **options)
  File "/home/ada/backtoshops-env/local/lib/python2.7/site-packages/sorl/thumbnail/base.py", line 65, in get_thumbnail
    default.kvstore.get_or_set(source)
  File "/home/ada/backtoshops-env/local/lib/python2.7/site-packages/sorl/thumbnail/kvstores/base.py", line 49, in get_or_set
    self.set(image_file)
  File "/home/ada/backtoshops-env/local/lib/python2.7/site-packages/sorl/thumbnail/kvstores/base.py", line 32, in set
    image_file.set_size() # make sure its got a size
  File "/home/ada/backtoshops-env/local/lib/python2.7/site-packages/sorl/thumbnail/images.py", line 108, in set_size
    image = default.engine.get_image(self)
  File "/home/ada/backtoshops-env/local/lib/python2.7/site-packages/sorl/thumbnail/engines/pil_engine.py", line 12, in get_image
    buf = StringIO(source.read())
  File "/home/ada/backtoshops-env/local/lib/python2.7/site-packages/sorl/thumbnail/images.py", line 121, in read
    return self.storage.open(self.name).read()
  File "/home/ada/backtoshops-env/local/lib/python2.7/site-packages/django/core/files/storage.py", line 36, in open
    return self._open(name, mode)
  File "/home/ada/svn/backtoshops/backtoshops/common/assets_utils.py", line 41, in _open
    return urllib2.urlopen(self.url(name))
  File "/usr/lib/python2.7/urllib2.py", line 126, in urlopen
    return _opener.open(url, data, timeout)
  File "/usr/lib/python2.7/urllib2.py", line 400, in open
    response = self._open(req, data)
  File "/usr/lib/python2.7/urllib2.py", line 418, in _open
    '_open', req)
  File "/usr/lib/python2.7/urllib2.py", line 378, in _call_chain
    result = func(*args)
  File "/usr/lib/python2.7/urllib2.py", line 1207, in http_open
    return self.do_open(httplib.HTTPConnection, req)
  File "/usr/lib/python2.7/urllib2.py", line 1177, in do_open
    raise URLError(err)
URLError: <urlopen error [Errno 111] Connection refused>
ERROR Thu, 08 May 2014 08:52:50 +0000 base 3705 140308054341376 Internal Server Error: /sales/list/current/
Traceback (most recent call last):
  File "/home/ada/backtoshops-env/local/lib/python2.7/site-packages/django/core/handlers/base.py", line 140, in get_response
    response = response.render()
  File "/home/ada/backtoshops-env/local/lib/python2.7/site-packages/django/template/response.py", line 105, in render
    self.content = self.rendered_content
  File "/home/ada/backtoshops-env/local/lib/python2.7/site-packages/django/template/response.py", line 82, in rendered_content
    content = template.render(context)
  File "/home/ada/backtoshops-env/local/lib/python2.7/site-packages/django/template/base.py", line 140, in render
    return self._render(context)
  File "/home/ada/backtoshops-env/local/lib/python2.7/site-packages/django/template/base.py", line 134, in _render
    return self.nodelist.render(context)
  File "/home/ada/backtoshops-env/local/lib/python2.7/site-packages/django/template/base.py", line 830, in render
    bit = self.render_node(node, context)
  File "/home/ada/backtoshops-env/local/lib/python2.7/site-packages/django/template/debug.py", line 74, in render_node
    return node.render(context)
  File "/home/ada/backtoshops-env/local/lib/python2.7/site-packages/django/template/loader_tags.py", line 124, in render
    return compiled_parent._render(context)
  File "/home/ada/backtoshops-env/local/lib/python2.7/site-packages/django/template/base.py", line 134, in _render
    return self.nodelist.render(context)
  File "/home/ada/backtoshops-env/local/lib/python2.7/site-packages/django/template/base.py", line 830, in render
    bit = self.render_node(node, context)
  File "/home/ada/backtoshops-env/local/lib/python2.7/site-packages/django/template/debug.py", line 74, in render_node
    return node.render(context)
  File "/home/ada/backtoshops-env/local/lib/python2.7/site-packages/django/template/loader_tags.py", line 63, in render
    result = block.nodelist.render(context)
  File "/home/ada/backtoshops-env/local/lib/python2.7/site-packages/django/template/base.py", line 830, in render
    bit = self.render_node(node, context)
  File "/home/ada/backtoshops-env/local/lib/python2.7/site-packages/django/template/debug.py", line 74, in render_node
    return node.render(context)
  File "/home/ada/backtoshops-env/local/lib/python2.7/site-packages/django/template/defaulttags.py", line 188, in render
    nodelist.append(node.render(context))
  File "/home/ada/backtoshops-env/local/lib/python2.7/site-packages/sorl/thumbnail/templatetags/thumbnail.py", line 45, in render
    return self._render(context)
  File "/home/ada/backtoshops-env/local/lib/python2.7/site-packages/sorl/thumbnail/templatetags/thumbnail.py", line 97, in _render
    file_, geometry, **options
  File "/home/ada/svn/backtoshops/backtoshops/../backtoshops/init.py", line 8, in get_thumbnail
    thumbnail = super(CustomThumbnailBackend, self).get_thumbnail(file, geometry_string, **options)
  File "/home/ada/backtoshops-env/local/lib/python2.7/site-packages/sorl/thumbnail/base.py", line 65, in get_thumbnail
    default.kvstore.get_or_set(source)
  File "/home/ada/backtoshops-env/local/lib/python2.7/site-packages/sorl/thumbnail/kvstores/base.py", line 49, in get_or_set
    self.set(image_file)
  File "/home/ada/backtoshops-env/local/lib/python2.7/site-packages/sorl/thumbnail/kvstores/base.py", line 32, in set
    image_file.set_size() # make sure its got a size
  File "/home/ada/backtoshops-env/local/lib/python2.7/site-packages/sorl/thumbnail/images.py", line 108, in set_size
    image = default.engine.get_image(self)
  File "/home/ada/backtoshops-env/local/lib/python2.7/site-packages/sorl/thumbnail/engines/pil_engine.py", line 12, in get_image
    buf = StringIO(source.read())
  File "/home/ada/backtoshops-env/local/lib/python2.7/site-packages/sorl/thumbnail/images.py", line 121, in read
    return self.storage.open(self.name).read()
  File "/home/ada/backtoshops-env/local/lib/python2.7/site-packages/django/core/files/storage.py", line 36, in open
    return self._open(name, mode)
  File "/home/ada/svn/backtoshops/backtoshops/common/assets_utils.py", line 41, in _open
    return urllib2.urlopen(self.url(name))
  File "/usr/lib/python2.7/urllib2.py", line 126, in urlopen
    return _opener.open(url, data, timeout)
  File "/usr/lib/python2.7/urllib2.py", line 400, in open
    response = self._open(req, data)
  File "/usr/lib/python2.7/urllib2.py", line 418, in _open
    '_open', req)
  File "/usr/lib/python2.7/urllib2.py", line 378, in _call_chain
    result = func(*args)
  File "/usr/lib/python2.7/urllib2.py", line 1207, in http_open
    return self.do_open(httplib.HTTPConnection, req)
  File "/usr/lib/python2.7/urllib2.py", line 1177, in do_open
    raise URLError(err)
URLError: <urlopen error [Errno 111] Connection refused>
